Workbook

Sheet Assumptions
A1: TECHNO-ECONOMIC ANALYSIS — NAPHTHA HYDRODESULFURIZATION (HDS) PLANT
A2: Plant Basis: Fixed-bed catalytic reactor | Currency: USD | Basis Year: 2026
A3: LEGEND: | B3: Input (blue = hardcoded) | C3: Formula (calculated) | D3: Cross-sheet link (green) | E3: Total / KPI
A5: 1.1 PLANT BASIS
A6: Parameter | B6: Value | C6: Units | D6: Notes / Source
A7: Process type | B7: Hydrodesulfurization (HDS) | C7: – | D7: Fixed-bed catalytic reactor
A8: Feedstock | B8: Sour naphtha | C8: – | D8: Stream NAPHTHA from simulation
A9: Feed rate | B9: 3 | C9: t/h | D9: Mass flow from process simulation
A10: Operating hours/year | B10: 8000 | C10: h/yr | D10: 91% on-stream factor
A11: Annual feed throughput | B11: =B9*B10 -> 24000 | C11: t/yr | D11: Feed rate × Operating hours
A12: Sweet naphtha yield | B12: 99.2 | C12: % | D12: Based on S14+S16 stream mass flows
A13: Annual product output | B13: =B11*(B12/100) -> 23808 | C13: t/yr | D13: Throughput × Yield %
A14: H₂ consumption | B14: 71.4 | C14: t/yr | D14: Stream H2 mass flow
A15: Amine (MDEA) makeup | B15: 85.2 | C15: t/yr | D15: Makeup loss replacement
A16: HDS catalyst charge | B16: 2000 | C16: kg | D16: Initial charge per reactor
A17: Catalyst replacement life | B17: 3 | C17: years | D17: Replace every 3 years
A18: Plant design life | B18: 20 | C18: years | D18: Economic evaluation horizon
A19: Depreciation period | B19: 10 | C19: years | D19: Straight-line, zero salvage
A21: 1.2 FINANCIAL ASSUMPTIONS
A22: Parameter | B22: Value | C22: Units | D22: Notes / Source
A23: Discount rate (WACC) | B23: 10 | C23: % | D23: Industry standard for NPV/IRR
A24: Corporate tax rate | B24: 30 | C24: % | D24: Corporate income tax rate
A25: Working capital basis | B25: 15 | C25: % OPEX | D25: Standard refinery assumption
A26: Year 1 ramp-up capacity | B26: 70 | C26: % | D26: Production at 70% in Year 1
A27: Year 2 ramp-up capacity | B27: 85 | C27: % | D27: Production at 85% in Year 2
A29: 1.3 PRICING FRAMEWORK (Realistic 2026 USD)
A30: Item | B30: Unit Price | C30: Units | D30: Notes / Source
A31: Sour naphtha (feedstock) | B31: 525 | C31: USD/t | D31: Discounted: high-sulfur content
A32: Sweet naphtha (product) | B32: 635 | C32: USD/t | D32: Premium: ultra-low sulfur <10 ppm
A33: Hydrogen (H₂) | B33: 1500 | C33: USD/t | D33: Grey H₂, refinery-grade supply
A34: MDEA amine | B34: 1570 | C34: USD/t | D34: Market price 2026
A35: HDS catalyst (CoMo/NiMo) | B35: 25 | C35: USD/kg | D35: Replaced every 3 years
A36: Cooling water | B36: 0.05 | C36: USD/t | D36: Once-through system
A37: Low-pressure steam (100 psig) | B37: 33.5 | C37: USD/t | D37: 3.5 bar steam
A38: Electricity | B38: 0.08 | C38: USD/kWh | D38: Industrial tariff
A40: 1.4 UTILITY COSTS (User-Provided Fixed Value from Simulation)
A41: Utility | B41: Annual Cost | C41: Units | D41: Notes
A42: Total utilities (electricity + cooling water + steam + process water) | B42: 147924 | C42: USD/yr | D42: User-provided fixed value from HYSYS/Aspen simulation

Sheet CAPEX
A1: CAPITAL EXPENDITURE (CAPEX) — NAPHTHA HDS PLANT
A2: All costs in USD | Q1 2026 basis | Lang-factor installation method
A3: LEGEND: | B3: Input (blue = hardcoded) | C3: Formula (calculated) | D3: Cross-sheet link (green) | E3: Total / KPI
A5: 2.1 EQUIPMENT COST BREAKDOWN (ISBL — Inside Battery Limits)
A6: Equipment / Item | B6: Size / Duty | C6: Bare Cost (USD) | D6: Install Factor | E6: Installed Cost (USD) | F6: Notes
A7: Compressor package (COMP1 + COMP2) | B7: 15 kW total, 41 bar | C7: 50000 | D7: 4 | E7: =C7*D7 -> 200000
A8: Heat exchanger — HX1 (feed preheat) | B8: 10 m², 350°C, 41 bar | C8: 12000 | D8: 4 | E8: =C8*D8 -> 48000
A9: Heat exchanger — HX2 (pre-reactor) | B9: 8 m², process-to-process | C9: 8000 | D9: 4 | E9: =C9*D9 -> 32000
A10: Heat exchanger — HX3 (product cool) | B10: 15 m², 40→60°C | C10: 14000 | D10: 4 | E10: =C10*D10 -> 56000
A11: Heat exchanger — HX4 (reboiler) | B11: 12 m², column duty | C11: 11000 | D11: 4 | E11: =C11*D11 -> 44000
A12: Heat exchanger — HX5 (recycle cool) | B12: 6 m², gas cooler | C12: 7000 | D12: 4 | E12: =C12*D12 -> 28000
A13: Fixed-bed HDS reactor (REACTOR) | B13: 0.5 m³, 350°C, 41 bar | C13: 40000 | D13: 4 | E13: =C13*D13 -> 160000
A14: HP flash drum (FLASH) | B14: 1 m³, 31 bar | C14: 15000 | D14: 4 | E14: =C14*D14 -> 60000
A15: LP flash drum (pre-separator) | B15: 1 m³, 4 bar | C15: 12000 | D15: 4 | E15: =C15*D15 -> 48000
A16: Amine absorber (ABSORBER) | B16: 0.6 m dia × 8 m packed | C16: 35000 | D16: 4 | E16: =C16*D16 -> 140000
A17: Distillation column (DIST) | B17: 0.5 m dia × 6 m | C17: 32000 | D17: 4 | E17: =C17*D17 -> 128000
A18: Feed pump (PUMP) | B18: 5 kW, 41 bar | C18: 8000 | D18: 4 | E18: =C18*D18 -> 32000
... A24: Electrical installation | B24: MCC, cabling, earthing | C24: 20000 | D24: 4 | E24: =C24*D24 -> 80000
A25: TOTAL INSTALLED COST (ISBL) | C25: =SUM(C7:C24) -> 418000 | E25: =SUM(E7:E24) -> 1672000
A27: 2.2 PROJECT COST STRUCTURE (ISBL → FCI → TCI)
A28: Cost Component | B28: Basis | C28: Amount (USD) | D28: – | E28: – | F28: Notes
A29: Engineering & Project Management | B29: 15% of ISBL | C29: =E25*0.15 -> 250800
A30: Contingency (process risk, scope growth) | B30: 15% of ISBL | C30: =E25*0.15 -> 250800
A31: Fixed Capital Investment (FCI) | B31: ISBL + Engineering + Contingency | C31: =E25+C29+C30 -> 2173600
A32: OSBL + Owner's costs + Licence fees | B32: 40% of FCI — accounts for OSBL, commissioning, owner costs | C32: =C31*0.4 -> 869440
A33: Land & site preparation | B33: Lump sum — site already acquired | C33: 50000
A34: ▶ TOTAL CAPITAL INVESTMENT (TCI) — User Provided | B34: From simulation & quotation — ANCHOR CELL | C34: 5948430
A35: Working Capital (dynamic — 15% × OPEX) | B35: wc% × Total Annual OPEX | C35: =OPEX!D34*(Assumptions!B25/100) -> 1997317.5
A37: 2.3 STRAIGHT-LINE DEPRECIATION SCHEDULE (Zero Salvage Value)
A38: Annual Depreciation = TCI ÷ Depreciation Period | B38: =C34/Assumptions!B19 -> 594843 | C38: =1/Assumptions!B19 -> 0.1 | D38: USD/yr | E38: =C34 -> 5948430 | F38: ← TCI linked from above
A39: Year | B39: Annual Depreciation (USD) | C39: Cumulative Depreciation (USD) | D39: Remaining Book Value (USD) | E39: Depr. Rate (%) | F39: Status
A40: 1 | B40: =C34/Assumptions!B19 -> 594843 | C40: =SUM(B40:B40) -> 594843 | D40: =C34-C40 -> 5353587 | E40: =1/Assumptions!B19 -> 0.1
A41: 2 | B41: =C34/Assumptions!B19 -> 594843 | C41: =SUM(B40:B41) -> 1189686 | D41: =C34-C41 -> 4758744 | E41: =1/Assumptions!B19 -> 0.1
A42: 3 | B42: =C34/Assumptions!B19 -> 594843 | C42: =SUM(B40:B42) -> 1784529 | D42: =C34-C42 -> 4163901 | E42: =1/Assumptions!B19 -> 0.1
A43: 4 | B43: =C34/Assumptions!B19 -> 594843 | C43: =SUM(B40:B43) -> 2379372 | D43: =C34-C43 -> 3569058 | E43: =1/Assumptions!B19 -> 0.1
A44: 5 | B44: =C34/Assumptions!B19 -> 594843 | C44: =SUM(B40:B44) -> 2974215 | D44: =C34-C44 -> 2974215 | E44: =1/Assumptions!B19 -> 0.1
A45: 6 | B45: =C34/Assumptions!B19 -> 594843 | C45: =SUM(B40:B45) -> 3569058 | D45: =C34-C45 -> 2379372 | E45: =1/Assumptions!B19 -> 0.1
A46: 7 | B46: =C34/Assumptions!B19 -> 594843 | C46: =SUM(B40:B46) -> 4163901 | D46: =C34-C46 -> 1784529 | E46: =1/Assumptions!B19 -> 0.1
A47: 8 | B47: =C34/Assumptions!B19 -> 594843 | C47: =SUM(B40:B47) -> 4758744 | D47: =C34-C47 -> 1189686 | E47: =1/Assumptions!B19 -> 0.1
A48: 9 | B48: =C34/Assumptions!B19 -> 594843 | C48: =SUM(B40:B48) -> 5353587 | D48: =C34-C48 -> 594843 | E48: =1/Assumptions!B19 -> 0.1
...

Sheet OPEX
A1: ANNUAL OPERATING EXPENDITURE (OPEX) — NAPHTHA HDS PLANT
A2: All costs in USD/year | Basis: 100% capacity (8,000 h/yr) | All values formula-driven
A3: LEGEND: | B3: Input (blue = hardcoded) | C3: Formula (calculated) | D3: Cross-sheet link (green) | E3: Total / KPI
A5: 3.1 VARIABLE OPERATING COSTS (scale with production volume)
A6: Category | B6: Component | C6: Calculation Basis | D6: Annual Cost (USD) | E6: % of Total OPEX
A7: FEEDSTOCK
A8: Feedstock | B8: Sour naphtha | C8: Annual throughput × price | D8: =Assumptions!B11*Assumptions!B31 -> 12600000 | E8: =D8/D34 -> 0.9462692
A9: CHEMICALS
A10: Chemicals | B10: Hydrogen (H₂) | C10: H₂ consumption × price | D10: =Assumptions!B14*Assumptions!B33 -> 107100 | E10: =D10/D34 -> 0.0080432882
A11: Chemicals | B11: MDEA amine makeup | C11: Makeup qty × unit price | D11: =Assumptions!B15*Assumptions!B34 -> 133764 | E11: =D11/D34 -> 0.010045774
A12: Chemicals | B12: HDS catalyst (annualised) | C12: Catalyst charge × price ÷ life | D12: =Assumptions!B16*Assumptions!B35/Assumptions!B17 -> 16666.667 | E12: =D12/D34 -> 0.0012516788
A13: UTILITIES
A14: Utilities | B14: All utilities (electricity, cooling water, steam) | C14: Fixed value from simulation | D14: =Assumptions!B42 -> 147924 | E14: =D14/D34 -> 0.0111092
B15: VARIABLE COST SUBTOTAL | D15: =D8+D10+D11+D12+D14 -> 13005455 | E15: =D15/D34 -> 0.97671915
A17: 3.2 FIXED OPERATING COSTS (independent of production volume)
A18: Category | B18: Component | C18: Calculation Basis | D18: Annual Cost (USD) | E18: % of Total OPEX
A19: MAINTENANCE & REPAIRS
A20: Maintenance | B20: Plant maintenance & repairs | C20: 3% of TCI (industry standard) | D20: =CAPEX!C34*0.03 -> 178452.9 | E20: =D20/D34 -> 0.013401943
A21: LABOUR & STAFFING
A22: Labour | B22: Operators (8 × $8,500/yr) | C22: Headcount × annual wage | D22: =8*8500 -> 68000 | E22: =D22/D34 -> 0.0051068497
A23: Labour | B23: Supervision (15% of operator cost) | C23: Supervision rate × operator cost | D23: =D22*0.15 -> 10200 | E23: =D23/D34 -> 0.00076602745
A24: Labour | B24: Laboratory & QC testing | C24: Lump sum estimate | D24: 10000 | E24: =D24/D34 -> 0.0007510073
A25: INSURANCE & OVERHEADS
A26: Insurance | B26: Plant all-risk insurance | C26: 0.5% of TCI (annual premium) | D26: =CAPEX!C34*0.005 -> 29742.15 | E26: =D26/D34 -> 0.0022336572
A27: Overhead | B27: General overhead (admin, IT, HSE) | C27: 20% of operator cost | D27: =D22*0.2 -> 13600 | E27: =D27/D34 -> 0.0010213699
B28: FIXED COST SUBTOTAL | D28: =D20+D22+D23+D24+D26+D27 -> 309995.05 | E28: =D28/D34 -> 0.023280855
A30: 3.3 TOTAL ANNUAL OPEX SUMMARY
A31: Line Item | B31: Component | C31: Basis | D31: Annual Cost (USD) | E31: % Share
A32: Variable Costs | B32: Feedstock + Chemicals + Utilities | C32: Scales with throughput | D32: =D15 -> 13005455 | E32: =D32/D34 -> 0.97671915
A33: Fixed Costs | B33: Maintenance + Labour + Insurance | C33: Independent of throughput | D33: =D28 -> 309995.05 | E33: =D33/D34 -> 0.023280855
A34: TOTAL ANNUAL OPEX (excl. Depreciation) | D34: =D32+D33 -> 13315450 | E34: =100% -> 1
A36: 3.4 OPEX BREAKDOWN BY COMPONENT (for audit & Pareto analysis)
A37: Component | B37: Annual Cost (USD) | C37: % of Total | D37: Cumulative % | E37: Type
A38: Sour naphtha feedstock | B38: =D8 -> 12600000 | C38: =B38/B49 -> 0.9462692 | D38: =C38 -> 0.9462692 | E38: Variable
A39: Hydrogen (H₂) | B39: =D10 -> 107100 | C39: =B39/B49 -> 0.0080432882 | D39: =D38+C39 -> 0.95431249 | E39: Variable
A40: MDEA amine makeup | B40: =D11 -> 133764 | C40: =B40/B49 -> 0.010045774 | D40: =D39+C40 -> 0.96435827 | E40: Variable
A41: HDS catalyst (annual) | B41: =D12 -> 16666.667 | C41: =B41/B49 -> 0.0012516788 | D41: =D40+C41 -> 0.96560994 | E41: Variable
A42: All utilities | B42: =D14 -> 147924 | C42: =B42/B49 -> 0.0111092 | D42: =D41+C42 -> 0.97671915 | E42: Variable
A43: Maintenance & repairs | B43: =D20 -> 178452.9 | C43: =B43/B49 -> 0.013401943 | D43: =D42+C43 -> 0.99012109 | E43: Fixed
A44: Operators (8 FTE) | B44: =D22 -> 68000 | C44: =B44/B49 -> 0.0051068497 | D44: =D43+C44 -> 0.99522794 | E44: Fixed
...

Sheet Profitability
A1: PROFITABILITY ANALYSIS — NAPHTHA HDS PLANT
A2: 20-Year DCF | Ramp-up: 70%→85%→100% | Discounted & Simple Payback | All formulas linked
A3: LEGEND: | B3: Input (blue = hardcoded) | C3: Formula (calculated) | D3: Cross-sheet link (green) | E3: Total / KPI
A5: 4.1 LINKED KEY ASSUMPTIONS (all driven from Assumptions / CAPEX / OPEX sheets)
A6: Parameter | B6: Value | C6: Units | D6: Formula Source | E6: – | F6: –
A7: Total Capital Investment (TCI) | B7: =CAPEX!C34 -> 5948430 | C7: USD | D7: Linked: CAPEX!C34
A8: Variable OPEX (full capacity) | B8: =OPEX!D15 -> 13005455 | C8: USD/yr | D8: Linked: OPEX!D15
A9: Fixed OPEX | B9: =OPEX!D28 -> 309995.05 | C9: USD/yr | D9: Linked: OPEX!D28
A10: Total Annual OPEX | B10: =OPEX!D34 -> 13315450 | C10: USD/yr | D10: Linked: OPEX!D34
A11: Full Annual Revenue (100% capacity) | B11: =Assumptions!B13*Assumptions!B32 -> 15118080 | C11: USD/yr | D11: Product output × Sweet naphtha price
A12: Annual Depreciation | B12: =CAPEX!C34/Assumptions!B19 -> 594843 | C12: USD/yr | D12: TCI ÷ Depreciation period
A13: Tax Rate | B13: =Assumptions!B24/100 -> 0.3 | D13: Linked from Assumptions
A14: Discount Rate (WACC) | B14: =Assumptions!B23/100 -> 0.1 | D14: Linked from Assumptions
A15: Working Capital | B15: =OPEX!D34*(Assumptions!B25/100) -> 1997317.5 | C15: USD | D15: 15% × Total OPEX
A16: Year 1 Capacity Factor | B16: =Assumptions!B26/100 -> 0.7 | D16: Ramp-up Year 1
A17: Year 2 Capacity Factor | B17: =Assumptions!B27/100 -> 0.85 | D17: Ramp-up Year 2
A19: 4.2 ANNUAL INCOME STATEMENT (Year 3+ Steady State — 100% Capacity)
A20: Line Item | B20: Amount (USD/yr) | C20: Notes | D20: – | E20: – | F20: –
A21: Revenue | B21: =B11 -> 15118080 | C21: Full capacity: output × sweet naphtha price
A22: Total OPEX (excl. Depr.) | B22: =B10 -> 13315450 | C22: Linked from OPEX sheet
A23: EBITDA | B23: =B21-B22 -> 1802630.3 | C23: revenue − OPEX
A24: Depreciation (10-yr SL) | B24: =B12 -> 594843 | C24: tci ÷ Depr.Period, linked from Assumptions
A25: EBIT (Operating Income) | B25: =B23-B24 -> 1207787.3 | C25: ebitda − Depreciation
A26: Income Tax | B26: =IF(B25>0,B13*B25,0) -> 362336.18 | C26: IF(ebit>0, tax rate × EBIT, 0))
A27: NET PROFIT (after tax) | B27: =B25-B26 -> 845451.1 | C27: ebit − Tax
A29: 4.3 ANNUAL FREE CASH FLOW (Steady State, Method: EBIT×(1-t)+Depr)
A30: Component | B30: Amount (USD/yr) | C30: Formula Used | D30: – | E30: – | F30: –
A31: EBIT × (1 − Tax Rate) | B31: =B25*(1-B13) -> 845451.1 | C31: After-tax operating income
A32: Add back: Depreciation | B32: =B12 -> 594843 | C32: Non-cash charge added back
A33: ANNUAL FREE CASH FLOW | B33: =B25*(1-B13)+B12 -> 1440294.1 | C33: ebit×(1-Tax) + Depreciation
A35: 4.4 DISCOUNTED CASH FLOW TABLE (20-Year Horizon | Ramp-Up Years 1–2 | WC Recovery Year 20)
A36: Year | B36: Capacity % | C36: Revenue (USD) | D36: Variable OPEX (USD) | E36: Fixed OPEX (USD) | F36: Total OPEX (USD) | G36: EBITDA (USD) | H36: Depreciation (USD) | I36: EBIT (USD) | J36: Tax (USD) | K36: Cash Flow (USD) | L36: Discount Factor | M36: Disc. CF (USD) | N36: Cumul. CF (USD) | O36: Cumul. DCF (USD) | P36: Notes
A37: 0 | B37: 0 | C37: 0 | D37: 0 | E37: 0 | F37: 0 | G37: 0 | H37: 0 | I37: 0 | J37: 0 | K37: =-$B$7 -> -5948430 | L37: 1 | M37: =K37*L37 -> -5948430 | N37: =K37 -> -5948430 | O37: =M37 -> -5948430 | P37: Initial investment
A38: 1 | B38: =B16 -> 0.7 | C38: =B38*$B$11 -> 10582656 | D38: =B38*$B$8 -> 9103818.3 | E38: =$B$9 -> 309995.05 | F38: =D38+E38 -> 9413813.3 | G38: =C38-F38 -> 1168842.7 | H38: =IF(A38>0,IF(A38<=Assumptions!$B$19,$B$12,0),0) -> 594843 | I38: =G38-H38 -> 573999.68 | J38: =IF(I38>0,$B$13*I38,0) -> 172199.91 | K38: =I38*(1-$B$13)+H38 -> 996642.78 | L38: =1/(1+$B$14)^A38 -> 0.90909091 | M38: =K38*L38 -> 906038.89 | N38: =N37+K38 -> -4951787.2 | O38: =O37+M38 -> -5042391.1 | P38: Ramp-up: 70%
A39: 2 | B39: =B17 -> 0.85 | C39: =B39*$B$11 -> 12850368 | D39: =B39*$B$8 -> 11054636 | E39: =$B$9 -> 309995.05 | F39: =D39+E39 -> 11364632 | G39: =C39-F39 -> 1485736.5 | H39: =IF(A39>0,IF(A39<=Assumptions!$B$19,$B$12,0),0) -> 594843 | I39: =G39-H39 -> 890893.48 | J39: =IF(I39>0,$B$13*I39,0) -> 267268.05 | K39: =I39*(1-$B$13)+H39 -> 1218468.4 | L39: =1/(1+$B$14)^A39 -> 0.82644628 | M39: =K39*L39 -> 1006998.7 | N39: =N38+K39 -> -3733318.8 | O39: =O38+M39 -> -4035392.4 | P39: Ramp-up: 85%
A40: 3 | B40: 1 | C40: =B40*$B$11 -> 15118080 | D40: =B40*$B$8 -> 13005455 | E40: =$B$9 -> 309995.05 | F40: =D40+E40 -> 13315450 | G40: =C40-F40 -> 1802630.3 | H40: =IF(A40>0,IF(A40<=Assumptions!$B$19,$B$12,0),0) -> 594843 | I40: =G40-H40 -> 1207787.3 | J40: =IF(I40>0,$B$13*I40,0) -> 362336.18 | K40: =I40*(1-$B$13)+H40 -> 1440294.1 | L40: =1/(1+$B$14)^A40 -> 0.7513148 | M40: =K40*L40 -> 1082114.3 | N40: =N39+K40 -> -2293024.7 | O40: =O39+M40 -> -2953278.1 | P40: Full capacity
A41: 4 | B41: 1 | C41: =B41*$B$11 -> 15118080 | D41: =B41*$B$8 -> 13005455 | E41: =$B$9 -> 309995.05 | F41: =D41+E41 -> 13315450 | G41: =C41-F41 -> 1802630.3 | H41: =IF(A41>0,IF(A41<=Assumptions!$B$19,$B$12,0),0) -> 594843 | I41: =G41-H41 -> 1207787.3 | J41: =IF(I41>0,$B$13*I41,0) -> 362336.18 | K41: =I41*(1-$B$13)+H41 -> 1440294.1 | L41: =1/(1+$B$14)^A41 -> 0.68301346 | M41: =K41*L41 -> 983740.25 | N41: =N40+K41 -> -852730.59 | O41: =O40+M41 -> -1969537.9
A42: 5 | B42: 1 | C42: =B42*$B$11 -> 15118080 | D42: =B42*$B$8 -> 13005455 | E42: =$B$9 -> 309995.05 | F42: =D42+E42 -> 13315450 | G42: =C42-F42 -> 1802630.3 | H42: =IF(A42>0,IF(A42<=Assumptions!$B$19,$B$12,0),0) -> 594843 | I42: =G42-H42 -> 1207787.3 | J42: =IF(I42>0,$B$13*I42,0) -> 362336.18 | K42: =I42*(1-$B$13)+H42 -> 1440294.1 | L42: =1/(1+$B$14)^A42 -> 0.62092132 | M42: =K42*L42 -> 894309.32 | N42: =N41+K42 -> 587563.51 | O42: =O41+M42 -> -1075228.6
A43: 6 | B43: 1 | C43: =B43*$B$11 -> 15118080 | D43: =B43*$B$8 -> 13005455 | E43: =$B$9 -> 309995.05 | F43: =D43+E43 -> 13315450 | G43: =C43-F43 -> 1802630.3 | H43: =IF(A43>0,IF(A43<=Assumptions!$B$19,$B$12,0),0) -> 594843 | I43: =G43-H43 -> 1207787.3 | J43: =IF(I43>0,$B$13*I43,0) -> 362336.18 | K43: =I43*(1-$B$13)+H43 -> 1440294.1 | L43: =1/(1+$B$14)^A43 -> 0.56447393 | M43: =K43*L43 -> 813008.47 | N43: =N42+K43 -> 2027857.6 | O43: =O42+M43 -> -262220.09
A44: 7 | B44: 1 | C44: =B44*$B$11 -> 15118080 | D44: =B44*$B$8 -> 13005455 | E44: =$B$9 -> 309995.05 | F44: =D44+E44 -> 13315450 | G44: =C44-F44 -> 1802630.3 | H44: =IF(A44>0,IF(A44<=Assumptions!$B$19,$B$12,0),0) -> 594843 | I44: =G44-H44 -> 1207787.3 | J44: =IF(I44>0,$B$13*I44,0) -> 362336.18 | K44: =I44*(1-$B$13)+H44 -> 1440294.1 | L44: =1/(1+$B$14)^A44 -> 0.51315812 | M44: =K44*L44 -> 739098.61 | N44: =N43+K44 -> 3468151.7 | O44: =O43+M44 -> 476878.52
...

Sheet Sensitivity
A1: SENSITIVITY ANALYSIS — NAPHTHA HDS PLANT
A2: One-at-a-time (OAT) analysis | Steady-state basis | All outputs formula-driven
A3: LEGEND: | B3: Input (blue = hardcoded) | C3: Formula (calculated) | D3: Cross-sheet link (green) | E3: Total / KPI
A5: BASE CASE REFERENCE (linked from model)
A6: Parameter | B6: Value | C6: Units | E6: Parameter | F6: Value | G6: Units
A7: TCI | B7: =CAPEX!C34 -> 5948430 | C7: USD | E7: Sour naphtha price | F7: =Assumptions!B31 -> 525 | G7: USD/t
A8: Total OPEX | B8: =OPEX!D34 -> 13315450 | C8: USD/yr | E8: Sweet naphtha price | F8: =Assumptions!B32 -> 635 | G8: USD/t
A9: Annual Revenue | B9: =Profitability!B21 -> 15118080 | C9: USD/yr | E9: Discount rate | F9: =Assumptions!B23 -> 10 | G9: %
A10: Net Profit (SS) | B10: =Profitability!B27 -> 845451.1 | C10: USD/yr | E10: Tax rate | F10: =Assumptions!B24 -> 30 | G10: %
A12: SENSITIVITY 1: SWEET NAPHTHA SELLING PRICE (Revenue sensitivity)
A13: Varying product selling price ±20% | Feedstock cost unchanged | Steady-state, 100% capacity
A14: Scenario | B14: Sweet Price (USD/t) | C14: Revenue (USD/yr) | D14: Total OPEX (USD/yr) | E14: EBITDA (USD/yr) | F14: EBIT (USD/yr) | G14: Net Profit (USD/yr) | H14: Payback (yrs) | I14: ROI (%)
A15: –20% ($508/t) | B15: 508 | C15: =Assumptions!B13*B15 -> 12094464 | D15: =OPEX!D34 -> 13315450 | E15: =C15-D15 -> -1220985.7 | F15: =E15-Profitability!B12 -> -1815828.7 | G15: =IF(F15>0,F15*(1-Profitability!B13),F15) -> -1815828.7 | H15: =IF(G15+CAPEX!B38>0,CAPEX!C34/(G15+CAPEX!B38),999) -> 999 | I15: =G15/CAPEX!C34 -> -0.30526185
A16: –15% ($539/t) | B16: 539.75 | C16: =Assumptions!B13*B16 -> 12850368 | D16: =OPEX!D34 -> 13315450 | E16: =C16-D16 -> -465081.72 | F16: =E16-Profitability!B12 -> -1059924.7 | G16: =IF(F16>0,F16*(1-Profitability!B13),F16) -> -1059924.7 | H16: =IF(G16+CAPEX!B38>0,CAPEX!C34/(G16+CAPEX!B38),999) -> 999 | I16: =G16/CAPEX!C34 -> -0.17818562
A17: –10% ($571/t) | B17: 571.5 | C17: =Assumptions!B13*B17 -> 13606272 | D17: =OPEX!D34 -> 13315450 | E17: =C17-D17 -> 290822.28 | F17: =E17-Profitability!B12 -> -304020.72 | G17: =IF(F17>0,F17*(1-Profitability!B13),F17) -> -304020.72 | H17: =IF(G17+CAPEX!B38>0,CAPEX!C34/(G17+CAPEX!B38),999) -> 20.453832 | I17: =G17/CAPEX!C34 -> -0.051109405
A18: –5% ($603/t) | B18: 603.25 | C18: =Assumptions!B13*B18 -> 14362176 | D18: =OPEX!D34 -> 13315450 | E18: =C18-D18 -> 1046726.3 | F18: =E18-Profitability!B12 -> 451883.28 | G18: =IF(F18>0,F18*(1-Profitability!B13),F18) -> 316318.3 | H18: =IF(G18+CAPEX!B38>0,CAPEX!C34/(G18+CAPEX!B38),999) -> 6.528405 | I18: =G18/CAPEX!C34 -> 0.053176771
A19: BASE ($635/t) | B19: =Assumptions!B32 -> 635 | C19: =Assumptions!B13*B19 -> 15118080 | D19: =OPEX!D34 -> 13315450 | E19: =C19-D19 -> 1802630.3 | F19: =E19-Profitability!B12 -> 1207787.3 | G19: =IF(F19>0,F19*(1-Profitability!B13),F19) -> 845451.1 | H19: =IF(G19+CAPEX!B38>0,CAPEX!C34/(G19+CAPEX!B38),999) -> 4.1300107 | I19: =G19/CAPEX!C34 -> 0.14213012
A20: +5% ($666/t) | B20: 666.75 | C20: =Assumptions!B13*B20 -> 15873984 | D20: =OPEX!D34 -> 13315450 | E20: =C20-D20 -> 2558534.3 | F20: =E20-Profitability!B12 -> 1963691.3 | G20: =IF(F20>0,F20*(1-Profitability!B13),F20) -> 1374583.9 | H20: =IF(G20+CAPEX!B38>0,CAPEX!C34/(G20+CAPEX!B38),999) -> 3.0203863 | I20: =G20/CAPEX!C34 -> 0.23108348
A21: +10% ($698/t) | B21: 698.5 | C21: =Assumptions!B13*B21 -> 16629888 | D21: =OPEX!D34 -> 13315450 | E21: =C21-D21 -> 3314438.3 | F21: =E21-Profitability!B12 -> 2719595.3 | G21: =IF(F21>0,F21*(1-Profitability!B13),F21) -> 1903716.7 | H21: =IF(G21+CAPEX!B38>0,CAPEX!C34/(G21+CAPEX!B38),999) -> 2.3807436 | I21: =G21/CAPEX!C34 -> 0.32003683
A22: +15% ($730/t) | B22: 730.25 | C22: =Assumptions!B13*B22 -> 17385792 | D22: =OPEX!D34 -> 13315450 | E22: =C22-D22 -> 4070342.3 | F22: =E22-Profitability!B12 -> 3475499.3 | G22: =IF(F22>0,F22*(1-Profitability!B13),F22) -> 2432849.5 | H22: =IF(G22+CAPEX!B38>0,CAPEX!C34/(G22+CAPEX!B38),999) -> 1.9646744 | I22: =G22/CAPEX!C34 -> 0.40899019
A23: +20% ($762/t) | B23: 762 | C23: =Assumptions!B13*B23 -> 18141696 | D23: =OPEX!D34 -> 13315450 | E23: =C23-D23 -> 4826246.3 | F23: =E23-Profitability!B12 -> 4231403.3 | G23: =IF(F23>0,F23*(1-Profitability!B13),F23) -> 2961982.3 | H23: =IF(G23+CAPEX!B38>0,CAPEX!C34/(G23+CAPEX!B38),999) -> 1.6723987 | I23: =G23/CAPEX!C34 -> 0.49794354
A26: SENSITIVITY 2: SOUR NAPHTHA FEED PRICE (Cost sensitivity)
A27: Varying feedstock cost ±20% | Product price unchanged | Steady-state, 100% capacity
A28: Scenario | B28: Sour Price (USD/t) | C28: Revenue (USD/yr) | D28: Total OPEX (USD/yr) | E28: EBITDA (USD/yr) | F28: EBIT (USD/yr) | G28: Net Profit (USD/yr) | H28: Payback (yrs) | I28: ROI (%)
A29: –20% ($420/t) | B29: 420 | C29: =Profitability!B21 -> 15118080 | D29: =OPEX!D34-OPEX!D8+Assumptions!B11*B29 -> 10795450 | E29: =C29-D29 -> 4322630.3 | F29: =E29-Profitability!B12 -> 3727787.3 | G29: =IF(F29>0,F29*(1-Profitability!B13),F29) -> 2609451.1 | H29: =IF(G29+CAPEX!B38>0,CAPEX!C34/(G29+CAPEX!B38),999) -> 1.8563933 | I29: =G29/CAPEX!C34 -> 0.43867896
A30: –15% ($446/t) | B30: 446.25 | C30: =Profitability!B21 -> 15118080 | D30: =OPEX!D34-OPEX!D8+Assumptions!B11*B30 -> 11425450 | E30: =C30-D30 -> 3692630.3 | F30: =E30-Profitability!B12 -> 3097787.3 | G30: =IF(F30>0,F30*(1-Profitability!B13),F30) -> 2168451.1 | H30: =IF(G30+CAPEX!B38>0,CAPEX!C34/(G30+CAPEX!B38),999) -> 2.152659 | I30: =G30/CAPEX!C34 -> 0.36454175
A31: –10% ($472/t) | B31: 472.5 | C31: =Profitability!B21 -> 15118080 | D31: =OPEX!D34-OPEX!D8+Assumptions!B11*B31 -> 12055450 | E31: =C31-D31 -> 3062630.3 | F31: =E31-Profitability!B12 -> 2467787.3 | G31: =IF(F31>0,F31*(1-Profitability!B13),F31) -> 1727451.1 | H31: =IF(G31+CAPEX!B38>0,CAPEX!C34/(G31+CAPEX!B38),999) -> 2.5614456 | I31: =G31/CAPEX!C34 -> 0.29040454
A32: –5% ($498/t) | B32: 498.75 | C32: =Profitability!B21 -> 15118080 | D32: =OPEX!D34-OPEX!D8+Assumptions!B11*B32 -> 12685450 | E32: =C32-D32 -> 2432630.3 | F32: =E32-Profitability!B12 -> 1837787.3 | G32: =IF(F32>0,F32*(1-Profitability!B13),F32) -> 1286451.1 | H32: =IF(G32+CAPEX!B38>0,CAPEX!C34/(G32+CAPEX!B38),999) -> 3.161882 | I32: =G32/CAPEX!C34 -> 0.21626733
A33: BASE ($525/t) | B33: =Assumptions!B31 -> 525 | C33: =Profitability!B21 -> 15118080 | D33: =OPEX!D34-OPEX!D8+Assumptions!B11*B33 -> 13315450 | E33: =C33-D33 -> 1802630.3 | F33: =E33-Profitability!B12 -> 1207787.3 | G33: =IF(F33>0,F33*(1-Profitability!B13),F33) -> 845451.1 | H33: =IF(G33+CAPEX!B38>0,CAPEX!C34/(G33+CAPEX!B38),999) -> 4.1300107 | I33: =G33/CAPEX!C34 -> 0.14213012
A34: +5% ($551/t) | B34: 551.25 | C34: =Profitability!B21 -> 15118080 | D34: =OPEX!D34-OPEX!D8+Assumptions!B11*B34 -> 13945450 | E34: =C34-D34 -> 1172630.3 | F34: =E34-Profitability!B12 -> 577787.28 | G34: =IF(F34>0,F34*(1-Profitability!B13),F34) -> 404451.1 | H34: =IF(G34+CAPEX!B38>0,CAPEX!C34/(G34+CAPEX!B38),999) -> 5.952632 | I34: =G34/CAPEX!C34 -> 0.067992915
A35: +10% ($577/t) | B35: 577.5 | C35: =Profitability!B21 -> 15118080 | D35: =OPEX!D34-OPEX!D8+Assumptions!B11*B35 -> 14575450 | E35: =C35-D35 -> 542630.28 | F35: =E35-Profitability!B12 -> -52212.717 | G35: =IF(F35>0,F35*(1-Profitability!B13),F35) -> -52212.717 | H35: =IF(G35+CAPEX!B38>0,CAPEX!C34/(G35+CAPEX!B38),999) -> 10.962215 | I35: =G35/CAPEX!C34 -> -0.0087775626
A36: +15% ($603/t) | B36: 603.75 | C36: =Profitability!B21 -> 15118080 | D36: =OPEX!D34-OPEX!D8+Assumptions!B11*B36 -> 15205450 | E36: =C36-D36 -> -87369.717 | F36: =E36-Profitability!B12 -> -682212.72 | G36: =IF(F36>0,F36*(1-Profitability!B13),F36) -> -682212.72 | H36: =IF(G36+CAPEX!B38>0,CAPEX!C34/(G36+CAPEX!B38),999) -> 999 | I36: =G36/CAPEX!C34 -> -0.11468786
A37: +20% ($630/t) | B37: 630 | C37: =Profitability!B21 -> 15118080 | D37: =OPEX!D34-OPEX!D8+Assumptions!B11*B37 -> 15835450 | E37: =C37-D37 -> -717369.72 | F37: =E37-Profitability!B12 -> -1312212.7 | G37: =IF(F37>0,F37*(1-Profitability!B13),F37) -> -1312212.7 | H37: =IF(G37+CAPEX!B38>0,CAPEX!C34/(G37+CAPEX!B38),999) -> 999 | I37: =G37/CAPEX!C34 -> -0.22059816
A40: SENSITIVITY 3: TOTAL CAPITAL INVESTMENT (TCI) (CAPEX overrun / saving)
A41: Varying TCI ±30% | Maintenance (3%×TCI) and Depreciation (TCI÷10) update dynamically | Revenue unchanged
A42: Scenario | B42: TCI (USD) | C42: Revenue (USD/yr) | D42: Total OPEX (USD/yr) | E42: EBITDA (USD/yr) | F42: EBIT (USD/yr) | G42: Net Profit (USD/yr) | H42: Payback (yrs) | I42: ROI (%)
A43: –30% ($4,163,900) | B43: 4163901 | C43: =Profitability!B21 -> 15118080 | D43: =OPEX!D34-OPEX!D20+B43*0.03 -> 13261914 | E43: =C43-D43 -> 1856166.2 | F43: =E43-B43/Assumptions!$B$19 -> 1439776.1 | G43: =IF(F43>0,F43*(1-Profitability!B13),F43) -> 1007843.2 | H43: =IF(F43*(1-Profitability!$B$13)+B43/Assumptions!$B$19>0,B43/F43*(1-Profitability!$B$13)+B43/Assumptions!$B$19,"N/A") -> 416392.12 | I43: =G43/CAPEX!C34 -> 0.16943012
A44: –20% ($4,758,744) | B44: 4758744 | C44: =Profitability!B21 -> 15118080 | D44: =OPEX!D34-OPEX!D20+B44*0.03 -> 13279759 | E44: =C44-D44 -> 1838320.9 | F44: =E44-B44/Assumptions!$B$19 -> 1362446.5 | G44: =IF(F44>0,F44*(1-Profitability!B13),F44) -> 953712.52 | H44: =IF(F44*(1-Profitability!$B$13)+B44/Assumptions!$B$19>0,B44/F44*(1-Profitability!$B$13)+B44/Assumptions!$B$19,"N/A") -> 475876.84 | I44: =G44/CAPEX!C34 -> 0.16033012
A45: –10% ($5,353,587) | B45: 5353587 | C45: =Profitability!B21 -> 15118080 | D45: =OPEX!D34-OPEX!D20+B45*0.03 -> 13297604 | E45: =C45-D45 -> 1820475.6 | F45: =E45-B45/Assumptions!$B$19 -> 1285116.9 | G45: =IF(F45>0,F45*(1-Profitability!B13),F45) -> 899581.81 | H45: =IF(F45*(1-Profitability!$B$13)+B45/Assumptions!$B$19>0,B45/F45*(1-Profitability!$B$13)+B45/Assumptions!$B$19,"N/A") -> 535361.62 | I45: =G45/CAPEX!C34 -> 0.15123012
A46: BASE ($5,948,430) | B46: =CAPEX!C34 -> 5948430 | C46: =Profitability!B21 -> 15118080 | D46: =OPEX!D34-OPEX!D20+B46*0.03 -> 13315450 | E46: =C46-D46 -> 1802630.3 | F46: =E46-B46/Assumptions!$B$19 -> 1207787.3 | G46: =IF(F46>0,F46*(1-Profitability!B13),F46) -> 845451.1 | H46: =IF(F46*(1-Profitability!$B$13)+B46/Assumptions!$B$19>0,B46/F46*(1-Profitability!$B$13)+B46/Assumptions!$B$19,"N/A") -> 594846.45 | I46: =G46/CAPEX!C34 -> 0.14213012
...
